Workbook
Name DEHIDRO: '[1]Despacho Potencia'!$B$502:$AA$547
Name DEHIDRO: '[2]Despacho Potencia'!$B$418:$AA$462
Name Disponibilidad: '[3]Reporte de Disponibilidad'!$A$2:$FN$382
Name Fecha: [3]Menu!$C$13
Name FECHA: '[4]MENU PRINCIPAL'!$H$6
Name Gen_ini: [5]Gen_Mot!$C$4
Name Gendata: '[3]Reporte de Disponibilidad'!$A$2:$AX$413
Name MAXIMA: 5.5
Name MEDIA: 4.5
Name MINIMA: 3.5
Name RegPrimFre: [3]S_RPF!$A$11:$Y$77
Name RegPrimFre: [2]S_RPF!$A$11:$Y$77
Name RegSecFre: [3]S_RSF!$A$10:$Y$50
Name RegSecFre: [2]S_RSF!$A$10:$Y$40
Name ReserCaliente: [3]RTERM!$A$5:$Y$90
Name ReserCaliente: [2]RTERM!$A$5:$Y$90
Name ReserFria: [3]RFRIA!$A$7:$Y$75
Name ReserFria: [2]RFRIA!$A$7:$Y$75
Name SEMANA: '[6]MENU PRINCIPAL'!$G$9
Name SEMANA: '[4]MENU PRINCIPAL'!$G$9
Name Semana_1: [3]Menu!$C$14
Name Semana_1: [3]Menu!$C$14

Sheet ETIQUETA
P1: Elaborado Por: | Q1: Revisado Por: | R1: Aprobado Por: | S1: Programación: | T1: =+EOMONTH($L$17,-1)+1 -> 46174 | U1: =+IFERROR(WEEKDAY(T1),"") -> 2
T2: =IF($L$17>$T1,T1+1,"") -> 46175 | U2: =+IFERROR(WEEKDAY(T2),"") -> 3
T3: =IF($L$17>$T2,T2+1,"") -> 46176 | U3: =+IFERROR(WEEKDAY(T3),"") -> 4
T4: =IF($L$17>$T3,T3+1,"") -> 46177 | U4: =+IFERROR(WEEKDAY(T4),"") -> 5
T5: =IF($L$17>$T4,T4+1,"") -> 46178 | U5: =+IFERROR(WEEKDAY(T5),"") -> 6
T6: =IF($L$17>$T5,T5+1,"") | U6: =+IFERROR(WEEKDAY(T6),"")
T7: =IF($L$17>$T6,T6+1,"") | U7: =+IFERROR(WEEKDAY(T7),"")
T8: =IF($L$17>$T7,T7+1,"") | U8: =+IFERROR(WEEKDAY(T8),"")
T9: =IF($L$17>$T8,T8+1,"") | U9: =+IFERROR(WEEKDAY(T9),"")
T10: =IF($L$17>$T9,T9+1,"") | U10: 4
T11: =IF($L$17>$T10,T10+1,"") | U11: =+IFERROR(WEEKDAY(T11),"")
T12: =IF($L$17>$T11,T11+1,"") | U12: =+IFERROR(WEEKDAY(T12),"")
T13: =IF($L$17>$T12,T12+1,"") | U13: =+IFERROR(WEEKDAY(T13),"")
T14: =IF($L$17>$T13,T13+1,"") | U14: =+IFERROR(WEEKDAY(T14),"")
C16: ELABORACIÓN | F16: REVISIÓN | I16: APROBACIÓN | L16: FECHA DE SALIDA
C17: ALEXANDER DE LA CRUZ | F17: ALEXIS VÁSQUEZ | I17: ALEXIS VÁSQUEZ | L17: 46178
O19: =CELL("filename",K1) -> Y:\Gerencia Operaciones\3.PROGRAMACION\10.PROGRAMACION SEMANAL\2026\6.JUNIO\1. 06-06_12-06-2026\1.OC 70-2025\[VERIFICACION CVP_06-06_12-06-26.xlsx]ETIQUETA
O20: =RIGHT(O19,32) -> CVP_06-06_12-06-26.xlsx]ETIQUETA
O21: =LEFT(O20,18) -> CVP_06-06_12-06-26
O22: =CONCATENATE("SEMANA DEL "&O21) -> SEMANA DEL CVP_06-06_12-06-26
O23: =IF(COUNTIF($U$1:$U$14,4)=2,MONTH(T1-1),MONTH(T1-2)) -> 5

Sheet ESTATUS VERIFICACIÓN CEN
B1: ORGANISMO COORDINADOR DEL SISTEMA ELÉCTRICO NACIONAL INTERCONECTADO
B2: =CONCATENATE("Declaración CEN ", YEAR(EDATE(TODAY(),-1)), "-", ETIQUETA!$O$23) -> Declaración CEN 2026-5
B3: Empresa | C3: Id central o modalidad operativa | D3: Nombre de la central o modalidad operativa | E3: CEN declarado | F3: ¿SE APLICO ALGUNA ACCION CORRECTIVA? | G3: CEN utilizado | H3: COMENTARIOS ADICIONALES OC | I3: Unidad de medida del CEN
B4: AES ANDRES | C4: G3AANDFO | D4: AES ANDRÉS FO | F4: AUN NO DECLARADO | G4: =+VLOOKUP(C4,'COSTO VARIABLE DE PRODUCCIÓN'!$C$4:$H$57,6,0) -> 0.057318422 | I4: =+VLOOKUP(C4,'EXISTENCIA DE COMBUSTIBLE'!$C$4:$K$95,9,0) -> GALONES/KWh
B5: AES ANDRES | C5: G3AANDGN | D5: AES ANDRÉS GN | F5: AUN NO DECLARADO | G5: =+VLOOKUP(C5,'COSTO VARIABLE DE PRODUCCIÓN'!$C$4:$H$57,6,0) -> 0.0077921237 | I5: MMBTU/KWh
B6: BERSAL | C6: G3BERSAL | D6: BERSAL | F6: AUN NO DECLARADO | G6: =+VLOOKUP(C6,'COSTO VARIABLE DE PRODUCCIÓN'!$C$4:$H$57,6,0) -> 0.060526176 | I6: =+VLOOKUP(C6,'EXISTENCIA DE COMBUSTIBLE'!$C$4:$K$95,9,0) -> GALONES/KWh
B7: CESPM | C7: G3CES1FO | D7: CESPM 1 FO | F7: AUN NO DECLARADO | G7: =+VLOOKUP(C7,'COSTO VARIABLE DE PRODUCCIÓN'!$C$4:$H$57,6,0) -> 0.069981196 | I7: =+VLOOKUP(C7,'EXISTENCIA DE COMBUSTIBLE'!$C$4:$K$95,9,0) -> GALONES/KWh
B8: CESPM | C8: G3CES1GN | D8: CESPM 1 GN | F8: AUN NO DECLARADO | G8: =+VLOOKUP(C8,'COSTO VARIABLE DE PRODUCCIÓN'!$C$4:$H$57,6,0) -> 0.0084025827 | I8: =+VLOOKUP(C8,'EXISTENCIA DE COMBUSTIBLE'!$C$4:$K$95,9,0) -> MMBTU/KWh
B9: CESPM | C9: G3CES2FO | D9: CESPM 2 FO | F9: AUN NO DECLARADO | G9: =+VLOOKUP(C9,'COSTO VARIABLE DE PRODUCCIÓN'!$C$4:$H$57,6,0) -> 0.094942974 | I9: =+VLOOKUP(C9,'EXISTENCIA DE COMBUSTIBLE'!$C$4:$K$95,9,0) -> GALONES/KWh
B10: CESPM | C10: G3CES2GN | D10: CESPM 2 GN | F10: AUN NO DECLARADO | G10: =+VLOOKUP(C10,'COSTO VARIABLE DE PRODUCCIÓN'!$C$4:$H$57,6,0) -> 0.0083295576 | I10: =+VLOOKUP(C10,'EXISTENCIA DE COMBUSTIBLE'!$C$4:$K$95,9,0) -> MMBTU/KWh
B11: CESPM | C11: G3CES3FO | D11: CESPM 3 FO | F11: AUN NO DECLARADO | G11: =+VLOOKUP(C11,'COSTO VARIABLE DE PRODUCCIÓN'!$C$4:$H$57,6,0) -> 0.063224967 | I11: =+VLOOKUP(C11,'EXISTENCIA DE COMBUSTIBLE'!$C$4:$K$95,9,0) -> GALONES/KWh
B12: CESPM | C12: G3CES3GN | D12: CESPM 3 GN | F12: AUN NO DECLARADO | G12: =+VLOOKUP(C12,'COSTO VARIABLE DE PRODUCCIÓN'!$C$4:$H$57,6,0) -> 0.0083877907 | I12: =+VLOOKUP(C12,'EXISTENCIA DE COMBUSTIBLE'!$C$4:$K$95,9,0) -> MMBTU/KWh
B13: CESPM | C13: G3E4CCFO | D13: ENERGAS 4 CICLO COMBINADO FO | F13: AUN NO DECLARADO | G13: =+VLOOKUP(C13,'COSTO VARIABLE DE PRODUCCIÓN'!$C$4:$H$57,6,0) -> 0.054945319 | I13: =+VLOOKUP(C13,'EXISTENCIA DE COMBUSTIBLE'!$C$4:$K$95,9,0) -> GALONES/KWh
B14: CESPM | C14: G3E4CCGN | D14: ENERGAS 4 CICLO COMBINADO GN | F14: AUN NO DECLARADO | G14: =+VLOOKUP(C14,'COSTO VARIABLE DE PRODUCCIÓN'!$C$4:$H$57,6,0) -> 0.0072990159 | I14: =+VLOOKUP(C14,'EXISTENCIA DE COMBUSTIBLE'!$C$4:$K$95,9,0) -> MMBTU/KWh
B15: METALDOM | C15: G3METALD | D15: METALDOM | F15: AUN NO DECLARADO | G15: =+VLOOKUP(C15,'COSTO VARIABLE DE PRODUCCIÓN'!$C$4:$H$57,6,0) -> 0.064809449 | I15: =+VLOOKUP(C15,'EXISTENCIA DE COMBUSTIBLE'!$C$4:$K$95,9,0) -> GALONES/KWh
B16: DOMICEM GENERACIÓN | C16: G3PALENQ | D16: PALENQUE | F16: AUN NO DECLARADO | G16: =+VLOOKUP(C16,'COSTO VARIABLE DE PRODUCCIÓN'!$C$4:$H$57,6,0) -> 0.063873081 | I16: =+VLOOKUP(C16,'EXISTENCIA DE COMBUSTIBLE'!$C$4:$K$95,9,0) -> GALONES/KWh
B17: DPP | C17: G3LMINA5 | D17: LOS MINA 5 | F17: AUN NO DECLARADO | G17: =+VLOOKUP(C17,'COSTO VARIABLE DE PRODUCCIÓN'!$C$4:$H$57,6,0) -> 0.012250973 | I17: =+VLOOKUP(C17,'EXISTENCIA DE COMBUSTIBLE'!$C$4:$K$95,9,0) -> MMBTU/KWh
... B57: SAN PEDRO BIO-ENERGY | C57: G3SPBIOE | D57: SAN PEDRO BIO-ENERGY | F57: AUN NO DECLARADO | G57: =+VLOOKUP(C57,'COSTO VARIABLE DE PRODUCCIÓN'!$C$4:$H$57,6,0) -> 0.0021904759 | I57: =+VLOOKUP(C57,'EXISTENCIA DE COMBUSTIBLE'!$C$4:$K$95,9,0) -> TONELADAS METRICAS/KWh
B60: Leyenda:
C61: Pendiente por declarar o revisar CEN en los plazos establecidos en el procedimiento de la resolución OC 70-2025.
C62: Pendiente de aprobación de CEN en los plazos establecidos en el procedimiento de la resolución OC 70-2025.
B65: NOTAS:
B66: El término que se utiliza el Mercado Eléctrico Mayorista (según el art. 180 del RALGE 125-01 y el Procedimiento de la resolución OC 70-2025) es el Consumo Específico Neto (CEN), el cual tiene las unidades de medidas invertidas al del Ratio: gal/kwh para los combustibles líquidos, MMBTU/kwh para los combustibles gaseosos y TM/kwh para los combustibles sólidos, siendo a su vez calculados y declarados una vez por mes. Adicionalmente existen unas particularidades del CEN (CONSUMO DE COMBUSTIBLE/ENERGÍA NETA) que deben de ser tomadas en cuenta: 1. La componente ENERGÍA NETA corresponde a la energía que el generador inyectó a la red de transmisión, por lo tanto, no incluye la energía bruta desde los bornes del generador (es decir, no incluye los consumos propios ni las pérdidas de transformador del generador). 2. La componente de CONSUMO DE COMBUSTIBLE resulta del balance de la cantidad de combustible almacenado al inicio del mes correspondiente de la central en cuestión, más las compras de combustibles almacenadas durante el mes correspondiente para la central en cuestión, menos la cantidad de combustible almacenado al final del mes correspondiente de la central en cuestión (art. 5.5 del Procedimiento de la Resolución OC 70-2025), es decir: CONSUMO DE COMBUSTIBLE= Cantidad de combustible almacenado al inicio del mes + Compras durante el mes – Cantidad de combustible al final del mes. Los Agentes del MEM le remiten primero estos datos al Ministerio de Hacienda, y luego son reportados al OC como parte del sustento de su declaración. 3. Los Agentes del MEM tienen hasta el segundo miércoles de cada mes para realizar su declaración del CEN (con los valores de consumo y energía del mes anterior), una vez vencido el plazo para la declaración mensual, el valor del CEN permanece como un valor fijo hasta la próxima declaración mensual. 4. Los valores y observaciones del CEN mensual pueden encontrarse en la hoja “ESTATUS VERIFICACION CEN”, del archivo “VERIFICACION CVP_dd-mm_dd-mm-aa” (favor ver archivo adjunto), el cual es publicado en la página web de OC (y está disponible para todo el interesado) como parte de la programación semanal.
B68: COMPONENTES CVP | C68: FUEL OIL | D68: CARBÓN Y BIOMASA | E68: GAS NATURAL
B69: Consumo Especifico Neto | C69: Galones/kWh | D69: TON/kWh | E69: MMBTU/kWh

Sheet ESTADO DECLARACIÓN CVP
B1: ORGANISMO COORDINADOR DEL SISTEMA ELÉCTRICO NACIONAL INTERCONECTADO
B2: ="DECLARACIÓN CVP " &ETIQUETA!O21 -> DECLARACIÓN CVP CVP_06-06_12-06-26
B3: EMPRESA | C3: CÓDIGO CENTRAL | D3: CENTRAL | E3: CVP DECLARADO ($/MWh) | F3: ¿SE APLICO ALGUNA ACCION CORRECTIVA? | G3: CVP UTILIZADO ($/MWh) | H3: REGISTRO DE ACCIONES CORRECTIVAS SEGUN EL PROCEDIMIENTO DE LA RESOLUCION OC 70-2025
B4: AES ANDRES | C4: G3AANDGN | D4: AES ANDRÉS GN | E4: 79.831221 | F4: NO | G4: 79.831221
B5: AES ANDRES | C5: G3AANDFO | D5: AES ANDRÉS FO | E5: 214.75911 | F5: NO | G5: 214.75911
B6: BERSAL | C6: G3BERSAL | D6: BERSAL | E6: 158.12972 | F6: NO | G6: 158.12972 | V6: APROBADO
B7: CESPM | C7: G3CES2FO | D7: CESPM 2 FO | E7: 298.64745 | F7: SI | G7: 298.64745 | H7: Acorde a lo establecido en el párrafo primero literal (a) numeral 6.1.2 del procedimiento de la Resolución OC 70-2025, al agente responsable le fue realizada la observación siguiente: Estimado agente del MEM, hemos observado discrepancias en el valor declarado de Existencia Combustible Almacenado. Agradeceríamos que realice las aclaraciones o las verificaciones y ajustes de lugar. Dentro del plazo establecido en el literal (a) numeral 6.1.2 del Procedimiento de la Resolución OC 70-2025, el agente del MEM realizó las aclaraciones de lugar.
B8: CESPM | C8: G3E4CCFO | D8: ENERGAS 4 CICLO COMBINADO FO | E8: 172.83301 | F8: SI | G8: 172.83301 | H8: Acorde a lo establecido en el párrafo primero literal (a) numeral 6.1.2 del procedimiento de la Resolución OC 70-2025, al agente responsable le fue realizada la observación siguiente: Estimado agente del MEM, hemos observado discrepancias en el valor declarado de Existencia Combustible Almacenado. Agradeceríamos que realice las aclaraciones o las verificaciones y ajustes de lugar. Dentro del plazo establecido en el literal (a) numeral 6.1.2 del Procedimiento de la Resolución OC 70-2025, el agente del MEM realizó las aclaraciones de lugar.
B9: CESPM | C9: G3CES2GN | D9: CESPM 2 GN | E9: 57.820174 | F9: NO | G9: 57.820174
B10: CESPM | C10: G3CES1FO | D10: CESPM 1 FO | E10: 220.12904 | F10: SI | G10: 220.12904 | H10: Acorde a lo establecido en el párrafo primero literal (a) numeral 6.1.2 del procedimiento de la Resolución OC 70-2025, al agente responsable le fue realizada la observación siguiente: Estimado agente del MEM, hemos observado discrepancias en el valor declarado de Existencia Combustible Almacenado. Agradeceríamos que realice las aclaraciones o las verificaciones y ajustes de lugar. Dentro del plazo establecido en el literal (a) numeral 6.1.2 del Procedimiento de la Resolución OC 70-2025, el agente del MEM realizó las aclaraciones de lugar.
B11: CESPM | C11: G3E4CCGN | D11: ENERGAS 4 CICLO COMBINADO GN | E11: 77.47531 | F11: NO | G11: 77.47531
B12: CESPM | C12: G3CES1GN | D12: CESPM 1 GN | E12: 58.327082 | F12: NO | G12: 58.327082
B13: CESPM | C13: G3CES3FO | D13: CESPM 3 FO | E13: 198.87702 | F13: SI | G13: 198.87702 | H13: Acorde a lo establecido en el párrafo primero literal (a) numeral 6.1.2 del procedimiento de la Resolución OC 70-2025, al agente responsable le fue realizada la observación siguiente: Estimado agente del MEM, hemos observado discrepancias en el valor declarado de Existencia Combustible Almacenado. Agradeceríamos que realice las aclaraciones o las verificaciones y ajustes de lugar. Dentro del plazo establecido en el literal (a) numeral 6.1.2 del Procedimiento de la Resolución OC 70-2025, el agente del MEM realizó las aclaraciones de lugar.
B14: CESPM | C14: G3CES3GN | D14: CESPM 3 GN | E14: 58.224403 | F14: NO | G14: 58.224403
B15: METALDOM | C15: G3METALD | D15: METALDOM | F15: SI | G15: 6177.6367 | H15: En atención la autorización de la SIE para el inicio de salida comercial de la central METALDOM, y lo comunicado por el agente responsable de la misma de iniciar su desmantelamiento a partir del 26 de marzo 2026, y por lo tanto, su permanente indisponibilidad, no fue requerido la declaración de las componentes del CVP, permaneciendo su valor anterior hasta tanto se complete su salida de operación comercial.
B16: DOMICEM GENERACIÓN | C16: G3PALENQ | D16: PALENQUE | E16: 9467.5585 | F16: NO | G16: 9467.5585
B17: DPP | C17: G3PEMCT | D17: PARQUE ENERGETICO LOS MINA CC TOTAL | E17: 142.80855 | F17: NO | G17: 142.80855
B18: DPP | C18: G3PEMCP | D18: PARQUE ENERGETICO LOS MINA CC PARCIAL | E18: 144.65441 | F18: NO | G18: 144.65441
B19: DPP | C19: G3LMINA6 | D19: LOS MINA 6 | E19: 199.67203 | F19: NO | G19: 199.67203
B20: DPP | C20: G3LMINA5 | D20: LOS MINA 5 | E20: 198.37388 | F20: NO | G20: 198.37388
B21: ENERGíA 2000 | C21: G3MPLACS | D21: MANZANILLO POWER LAND CICLO SIMPLE | E21: 180.49249 | F21: NO | G21: 180.49249
B22: EGEHAINA | C22: G3QUI2GN | D22: QUISQUEYA 2 GN | E22: 58.932205 | F22: SI | G22: 58.932205 | H22: Acorde a lo establecido en el párrafo primero literal (a) numeral 6.1.2 del procedimiento de la Resolución OC 70-2025, al agente responsable le fue realizada la observación siguiente: Estimado agente del MEM, hemos observado una discrepancia en los sustentos presentados. Agradeceríamos que realice las aclaraciones o las verificaciones y ajustes de lugar. Dentro del plazo establecido en el literal (a) numeral 6.1.2 del Procedimiento de la Resolución OC 70-2025, el agente del MEM realizó las aclaraciones y los ajustes de lugar.
B23: EGEHAINA | C23: G3BCARBO | D23: BARAHONA CARBÓN | E23: 64.985525 | F23: NO | G23: 64.985525
B24: EGEHAINA | C24: G3HTG | D24: HAINA TG | E24: 217.69797 | F24: NO | G24: 217.69797
B25: EGEHAINA | C25: G3SESTE | D25: SULTANA DEL ESTE | E25: 127.95945 | F25: NO | G25: 127.95945
B26: EGEHAINA | C26: G3QUI2FO | D26: QUISQUEYA 2 FO | E26: 117.71908 | F26: NO | G26: 117.71908
B27: EGEITABO | C27: G3SLORE1 | D27: SAN LORENZO 1 | F27: SI | G27: 14229.868 | H27: Ante esta situación, se ha procedido acorde a lo establecido en el numeral 6.1.1 literal a) párrafo primero del Procedimiento de la Resolución OC 70-2025. En virtud a lo establecido en el numeral 6.1.1 literal a) párrafo tercero del Procedimiento de la Resolución OC 70-2025, por este medio se le notifica a todos los Agentes del MEM y a la SIE sobre el incumplimiento del plazo establecido para la declaración del precio de combustible puesto en planta.
B28: EGEITABO | C28: G3ITABO1 | D28: ITABO 1 | E28: 58.144845 | F28: SI | G28: 58.144845 | H28: Acorde a lo establecido en el párrafo primero literal (a) numeral 6.1.2 del procedimiento de la Resolución OC 70-2025, al agente responsable le fue realizada la observación siguiente: Estimado agente del MEM, hemos observado una discrepancia en el PCPP declarado. Agradeceríamos que realice las aclaraciones o las verificaciones y ajustes de lugar. Dentro del plazo establecido en el literal (a) numeral 6.1.2 del Procedimiento de la Resolución OC 70-2025, el agente del MEM realizó las aclaraciones de lugar.
B29: EGEITABO | C29: G3ITABO2 | D29: ITABO 2 | E29: 54.9374 | F29: SI | G29: 54.9374 | H29: Acorde a lo establecido en el párrafo primero literal (a) numeral 6.1.2 del procedimiento de la Resolución OC 70-2025, al agente responsable le fue realizada la observación siguiente: Estimado agente del MEM, hemos observado una discrepancia en el PCPP declarado. Agradeceríamos que realice las aclaraciones o las verificaciones y ajustes de lugar. Dentro del plazo establecido en el literal (a) numeral 6.1.2 del Procedimiento de la Resolución OC 70-2025, el agente del MEM realizó las aclaraciones de lugar.
B30: EMPRESA DE GENERACIÓN ELÉCTRICA PUNTA CATALINA | C30: G3PCATA2 | D30: PUNTA CATALINA 2 | E30: 31.353594 | F30: NO | G30: 31.353594
B31: EMPRESA DE GENERACIÓN ELÉCTRICA PUNTA CATALINA | C31: G3PCATA1 | D31: PUNTA CATALINA 1 | E31: 32.100812 | F31: NO | G31: 32.100812
B32: SEABOARD | C32: G3EM3CS | D32: ESTRELLA DEL MAR 3 CS | F32: SI | G32: ='COSTO VARIABLE DE PRODUCCIÓN'!K38/'COSTO VARIABLE DE PRODUCCIÓN'!M38 -> 91.109118 | H32: Ante esta situación, se ha procedido acorde a lo establecido en el numeral 6.1.1 literal a) párrafo primero del Procedimiento de la Resolución OC 70-2025. En virtud a lo establecido en el numeral 6.1.1 literal a) párrafo tercero del Procedimiento de la Resolución OC 70-2025, por este medio se le notifica a todos los Agentes del MEM y a la SIE sobre el incumplimiento del plazo establecido para la declaración del precio de combustible puesto en planta, y se ha procedido de acuerdo a lo establecido en el numeral 6.1.1 literal a) párrafo segundo de dicho procedimiento.
B33: SEABOARD | C33: G3EM2CGN | D33: ESTRELLA DEL MAR 2 CGN | F33: SI | G33: 93.631352 | H33: Ante esta situación, se ha procedido acorde a lo establecido en el numeral 6.1.1 literal a) párrafo primero del Procedimiento de la Resolución OC 70-2025. En virtud a lo establecido en el numeral 6.1.1 literal a) párrafo tercero del Procedimiento de la Resolución OC 70-2025, por este medio se le notifica a todos los Agentes del MEM y a la SIE sobre el incumplimiento del plazo establecido para la declaración del precio de combustible puesto en planta, y se ha procedido de acuerdo a lo establecido en el numeral 6.1.1 literal a) párrafo segundo de dicho procedimiento.
B34: SEABOARD | C34: G3EM2SGN | D34: ESTRELLA DEL MAR 2 SGN | F34: SI | G34: 98.400047 | H34: Ante esta situación, se ha procedido acorde a lo establecido en el numeral 6.1.1 literal a) párrafo primero del Procedimiento de la Resolución OC 70-2025. En virtud a lo establecido en el numeral 6.1.1 literal a) párrafo tercero del Procedimiento de la Resolución OC 70-2025, por este medio se le notifica a todos los Agentes del MEM y a la SIE sobre el incumplimiento del plazo establecido para la declaración del precio de combustible puesto en planta, y se ha procedido de acuerdo a lo establecido en el numeral 6.1.1 literal a) párrafo segundo de dicho procedimiento.
B35: SEABOARD | C35: G3EM2CFO | D35: ESTRELLA DEL MAR 2 CFO | F35: SI | G35: 126.53299 | H35: Ante esta situación, se ha procedido acorde a lo establecido en el numeral 6.1.1 literal a) párrafo primero del Procedimiento de la Resolución OC 70-2025. En virtud a lo establecido en el numeral 6.1.1 literal a) párrafo tercero del Procedimiento de la Resolución OC 70-2025, por este medio se le notifica a todos los Agentes del MEM y a la SIE sobre el incumplimiento del plazo establecido para la declaración del precio de combustible puesto en planta.
B36: SEABOARD | C36: G3EM2SFO | D36: ESTRELLA DEL MAR 2 SFO | F36: SI | G36: 133.20184 | H36: Ante esta situación, se ha procedido acorde a lo establecido en el numeral 6.1.1 literal a) párrafo primero del Procedimiento de la Resolución OC 70-2025. En virtud a lo establecido en el numeral 6.1.1 literal a) párrafo tercero del Procedimiento de la Resolución OC 70-2025, por este medio se le notifica a todos los Agentes del MEM y a la SIE sobre el incumplimiento del plazo establecido para la declaración del precio de combustible puesto en planta.
B37: SEABOARD | C37: G3EM3CCT | D37: ESTRELLA DEL MAR 3 CCT | F37: SI | G37: ='COSTO VARIABLE DE PRODUCCIÓN'!K37/'COSTO VARIABLE DE PRODUCCIÓN'!M37 -> 61.603103 | H37: Ante esta situación, se ha procedido acorde a lo establecido en el numeral 6.1.1 literal a) párrafo primero del Procedimiento de la Resolución OC 70-2025. En virtud a lo establecido en el numeral 6.1.1 literal a) párrafo tercero del Procedimiento de la Resolución OC 70-2025, por este medio se le notifica a todos los Agentes del MEM y a la SIE sobre el incumplimiento del plazo establecido para la declaración del precio de combustible puesto en planta, y se ha procedido de acuerdo a lo establecido en el numeral 6.1.1 literal a) párrafo segundo de dicho procedimiento.
B38: SEABOARD | C38: G3EM3CCP | D38: ESTRELLA DEL MAR 3 CCP | F38: SI | G38: ='COSTO VARIABLE DE PRODUCCIÓN'!K33/'COSTO VARIABLE DE PRODUCCIÓN'!M33 -> 62.453417 | H38: Ante esta situación, se ha procedido acorde a lo establecido en el numeral 6.1.1 literal a) párrafo primero del Procedimiento de la Resolución OC 70-2025. En virtud a lo establecido en el numeral 6.1.1 literal a) párrafo tercero del Procedimiento de la Resolución OC 70-2025, por este medio se le notifica a todos los Agentes del MEM y a la SIE sobre el incumplimiento del plazo establecido para la declaración del precio de combustible puesto en planta, y se ha procedido de acuerdo a lo establecido en el numeral 6.1.1 literal a) párrafo segundo de dicho procedimiento.
B39: GPLV | C39: G3PALAMA | D39: PALAMARA | E39: 147.48279 | F39: NO | G39: 147.48279
B40: GPLV | C40: G3LVEGA | D40: LA VEGA | E40: 151.4847 | F40: NO | G40: 151.4847
...

Sheet COSTO VARIABLE DE PRODUCCIÓN
A1: ORGANISMO COORDINADOR DEL SISTEMA ELÉCTRICO NACIONAL INTERCONECTADO
A2: ="COSTOS VARIABLES DE PRODUCCIÓN " &ETIQUETA!O21 -> COSTOS VARIABLES DE PRODUCCIÓN CVP_06-06_12-06-26
A3: PERIODO | B3: EMPRESA | C3: CENTRAL | D3: COMBUSTIBLE | E3: PRECIO COMBUSTIBLE (RD$/Unidad) | F3: TRANSPORTE (RD$/Unidad) | G3: PRECIO COMBUSTIBLE PUESTO EN PLANTA (RD$/Unidad) | H3: CONSUMO ESPECÍFICO | I3: COSTO VARIABLE COMBUSTIBLE (RD$/MWh) | J3: COSTO VARIABLE NO COMBUSTIBLE (RD$/MWh) | K3: CVP (RD$/MWh) | L3: COMBUSTIBLE ALMACENADO | M3: TASA | N3: PODER CALORÍFICO INFERIOR | O3: RENDIMIENTO | P3: DENSIDAD
A4: 2026-06-06 - 2026-06-12 | B4: AES ANDRES | C4: G3AANDGN | D4: Gas Natural | E4: 569.00995 | F4: 0 | G4: 569.00995 | H4: 0.0077921237 | I4: 4433.7959 | J4: 266.02775 | K4: 4699.8236 | L4: 1369807.2 | M4: 58.872 | N4: 1037 | O4: 128.33472 | P4: 0 | AM4: =+'ESTADO DECLARACIÓN CVP'!G4*'COSTO VARIABLE DE PRODUCCIÓN'!M4 -> 4699.8236 | AN4: =+VLOOKUP('ESTADO DECLARACIÓN CVP'!$C4,'COSTO VARIABLE DE PRODUCCIÓN'!$C$4:$K$57,9,FALSE) -> 4699.8236 | AO4: =+AM4=AN4 -> TRUE
A5: 2026-06-06 - 2026-06-12 | B5: AES ANDRES | C5: G3AANDFO | D5: Fuel Oil No. 2 | E5: 214.53369 | F5: 0 | G5: 214.53369 | H5: 0.057318422 | I5: 12296.732 | J5: 346.56581 | K5: 12643.298 | L5: 24500 | M5: 58.872 | N5: 0 | O5: 12.380546 | P5: 0 | AM5: =+'ESTADO DECLARACIÓN CVP'!G5*'COSTO VARIABLE DE PRODUCCIÓN'!M5 -> 12643.298 | AN5: =+VLOOKUP('ESTADO DECLARACIÓN CVP'!$C5,'COSTO VARIABLE DE PRODUCCIÓN'!$C$4:$K$57,9,FALSE) -> 12643.298 | AO5: =+AM5=AN5 -> TRUE
A6: 2026-06-06 - 2026-06-12 | B6: BERSAL | C6: G3BERSAL | D6: Fuel Oil No. 6 | E6: 147.89235 | F6: 0 | G6: 147.89235 | H6: 0.060526176 | I6: 8951.3585 | J6: 358.05434 | K6: 9309.4128 | L6: 84351.216 | M6: 58.872 | N6: 145536.72 | O6: 8808.7816 | P6: 918.24791 | AM6: =+'ESTADO DECLARACIÓN CVP'!G6*'COSTO VARIABLE DE PRODUCCIÓN'!M6 -> 9309.4128 | AN6: =+VLOOKUP('ESTADO DECLARACIÓN CVP'!$C6,'COSTO VARIABLE DE PRODUCCIÓN'!$C$4:$K$57,9,FALSE) -> 9309.4128 | AO6: =+AM6=AN6 -> TRUE
A7: 2026-06-06 - 2026-06-12 | B7: CESPM | C7: G3CES2GN | D7: Gas Natural | E7: 194.90621 | F7: 206.92651 | G7: 401.83272 | H7: 0.0083295576 | I7: 3347.0888 | J7: 56.900509 | K7: 3403.9893 | L7: 1936769.6 | M7: 58.872 | N7: 1042 | O7: 8329.5576 | P7: 0 | AM7: =+'ESTADO DECLARACIÓN CVP'!G7*'COSTO VARIABLE DE PRODUCCIÓN'!M7 -> 17581.973 | AN7: =+VLOOKUP('ESTADO DECLARACIÓN CVP'!$C7,'COSTO VARIABLE DE PRODUCCIÓN'!$C$4:$K$57,9,FALSE) -> 17581.973 | AO7: =+AM7=AN7 -> TRUE
A8: 2026-06-06 - 2026-06-12 | B8: CESPM | C8: G3CES1FO | D8: Fuel Oil No. 2 | E8: 174.70242 | F8: 0 | G8: 174.70242 | H8: 0.069981196 | I8: 12225.884 | J8: 733.55303 | K8: 12959.437 | L8: 236486.24 | M8: 58.872 | N8: 137345.54 | O8: 9611.6048 | P8: 875.61881 | AM8: =+'ESTADO DECLARACIÓN CVP'!G8*'COSTO VARIABLE DE PRODUCCIÓN'!M8 -> 10175.025 | AN8: =+VLOOKUP('ESTADO DECLARACIÓN CVP'!$C8,'COSTO VARIABLE DE PRODUCCIÓN'!$C$4:$K$57,9,FALSE) -> 10175.025 | AO8: =+AM8=AN8 -> TRUE
A9: 2026-06-06 - 2026-06-12 | B9: CESPM | C9: G3E4CCFO | D9: Fuel Oil No. 2 | E9: 174.70242 | F9: 0 | G9: 174.70242 | H9: 0.054945319 | I9: 9599.08 | J9: 575.9448 | K9: 10175.025 | L9: 236486.24 | M9: 58.872 | N9: 137345.54 | O9: 7546.4949 | P9: 875.61881 | AM9: =+'ESTADO DECLARACIÓN CVP'!G9*'COSTO VARIABLE DE PRODUCCIÓN'!M9 -> 3403.9893 | AN9: =+VLOOKUP('ESTADO DECLARACIÓN CVP'!$C9,'COSTO VARIABLE DE PRODUCCIÓN'!$C$4:$K$57,9,FALSE) -> 3403.9893 | AO9: =+AM9=AN9 -> TRUE
A10: 2026-06-06 - 2026-06-12 | B10: CESPM | C10: G3CES1GN | D10: Gas Natural | E10: 194.90621 | F10: 206.92651 | G10: 401.83272 | H10: 0.0084025827 | I10: 3376.4326 | J10: 57.399355 | K10: 3433.832 | L10: 1936769.6 | M10: 58.872 | N10: 1042 | O10: 8402.5827 | P10: 0 | AM10: =+'ESTADO DECLARACIÓN CVP'!G10*'COSTO VARIABLE DE PRODUCCIÓN'!M10 -> 12959.437 | AN10: =+VLOOKUP('ESTADO DECLARACIÓN CVP'!$C10,'COSTO VARIABLE DE PRODUCCIÓN'!$C$4:$K$57,9,FALSE) -> 12959.437 | AO10: =+AM10=AN10 -> TRUE
A11: 2026-06-06 - 2026-06-12 | B11: CESPM | C11: G3CES3FO | D11: Fuel Oil No. 2 | E11: 174.70242 | F11: 0 | G11: 174.70242 | H11: 0.063224967 | I11: 11045.555 | J11: 662.73327 | K11: 11708.288 | L11: 236486.24 | M11: 58.872 | N11: 137345.54 | O11: 8683.667 | P11: 875.61881 | AM11: =+'ESTADO DECLARACIÓN CVP'!G11*'COSTO VARIABLE DE PRODUCCIÓN'!M11 -> 4561.1265 | AN11: =+VLOOKUP('ESTADO DECLARACIÓN CVP'!$C11,'COSTO VARIABLE DE PRODUCCIÓN'!$C$4:$K$57,9,FALSE) -> 4561.1265 | AO11: =+AM11=AN11 -> TRUE
A12: 2026-06-06 - 2026-06-12 | B12: CESPM | C12: G3CES2FO | D12: Fuel Oil No. 2 | E12: 174.70242 | F12: 0 | G12: 174.70242 | H12: 0.094942974 | I12: 16586.767 | J12: 995.20601 | K12: 17581.973 | L12: 236486.24 | M12: 58.872 | N12: 137345.54 | O12: 13039.994 | P12: 875.61881 | AM12: =+'ESTADO DECLARACIÓN CVP'!G12*'COSTO VARIABLE DE PRODUCCIÓN'!M12 -> 3433.832 | AN12: =+VLOOKUP('ESTADO DECLARACIÓN CVP'!$C12,'COSTO VARIABLE DE PRODUCCIÓN'!$C$4:$K$57,9,FALSE) -> 3433.832 | AO12: =+AM12=AN12 -> TRUE
A13: 2026-06-06 - 2026-06-12 | B13: CESPM | C13: G3CES3GN | D13: Gas Natural | E13: 194.90621 | F13: 206.92651 | G13: 401.83272 | H13: 0.0083877907 | I13: 3370.4887 | J13: 57.298309 | K13: 3427.787 | L13: 1936769.6 | M13: 58.872 | N13: 1042 | O13: 8387.7907 | P13: 0 | AM13: =+'ESTADO DECLARACIÓN CVP'!G13*'COSTO VARIABLE DE PRODUCCIÓN'!M13 -> 11708.288 | AN13: =+VLOOKUP('ESTADO DECLARACIÓN CVP'!$C13,'COSTO VARIABLE DE PRODUCCIÓN'!$C$4:$K$57,9,FALSE) -> 11708.288 | AO13: =+AM13=AN13 -> TRUE
A14: 2026-06-06 - 2026-06-12 | B14: CESPM | C14: G3E4CCGN | D14: Gas Natural | E14: 614.45043 | F14: 0 | G14: 614.45043 | H14: 0.0072990159 | I14: 4484.8835 | J14: 76.243019 | K14: 4561.1265 | L14: 410298.08 | M14: 58.872 | N14: 1042 | O14: 7299.0159 | P14: 0 | AM14: =+'ESTADO DECLARACIÓN CVP'!G14*'COSTO VARIABLE DE PRODUCCIÓN'!M14 -> 3427.787 | AN14: =+VLOOKUP('ESTADO DECLARACIÓN CVP'!$C14,'COSTO VARIABLE DE PRODUCCIÓN'!$C$4:$K$57,9,FALSE) -> 3427.787 | AO14: =+AM14=AN14 -> TRUE
A15: 2026-06-06 - 2026-06-12 | B15: METALDOM | C15: G3METALD | D15: Fuel Oil No. 6 | E15: 93.32 | F15: 2 | G15: 95.32 | H15: 0.064809449 | I15: 6177.6367 | J15: 0 | K15: 6177.6367 | L15: 220000 | M15: 58.872 | N15: 148842.14 | O15: 8955.8883 | P15: 957.43342 | AM15: =+'ESTADO DECLARACIÓN CVP'!G15 -> 6177.6367 | AN15: =+VLOOKUP('ESTADO DECLARACIÓN CVP'!$C15,'COSTO VARIABLE DE PRODUCCIÓN'!$C$4:$K$57,9,FALSE) -> 6177.6367 | AO15: =+AM15=AN15 -> TRUE
A16: 2026-06-06 - 2026-06-12 | B16: DOMICEM GENERACIÓN | C16: G3PALENQ | D16: Fuel Oil No. 6 | E16: 142.5236 | F16: 0 | G16: 142.5236 | H16: 0.063873081 | I16: 9103.4216 | J16: 364.13687 | K16: 9467.5585 | L16: 122050.1 | M16: 58.872 | N16: 138058.81 | O16: 8722.0484 | P16: 928.39882 | AM16: =+'ESTADO DECLARACIÓN CVP'!G16 -> 9467.5585 | AN16: =+VLOOKUP('ESTADO DECLARACIÓN CVP'!$C16,'COSTO VARIABLE DE PRODUCCIÓN'!$C$4:$K$57,9,FALSE) -> 9467.5585 | AO16: =+AM16=AN16 -> TRUE
A17: 2026-06-06 - 2026-06-12 | B17: DPP | C17: G3LMINA5 | D17: Gas Natural | E17: 934.593 | F17: 0 | G17: 934.593 | H17: 0.012250973 | I17: 11449.674 | J17: 228.99348 | K17: 11678.667 | L17: 0 | M17: 58.872 | N17: 1037 | O17: 81.626168 | P17: 0 | AM17: =+'ESTADO DECLARACIÓN CVP'!G17*'COSTO VARIABLE DE PRODUCCIÓN'!M17 -> 8407.4247 | AN17: =+VLOOKUP('ESTADO DECLARACIÓN CVP'!$C17,'COSTO VARIABLE DE PRODUCCIÓN'!$C$4:$K$57,9,FALSE) -> 8407.4247 | AO17: =+AM17=AN17 -> TRUE
A18: 2026-06-06 - 2026-06-12 | B18: DPP | C18: G3LMINA6 | D18: Gas Natural | E18: 934.593 | F18: 0 | G18: 934.593 | H18: 0.012331143 | I18: 11524.6 | J18: 230.492 | K18: 11755.092 | L18: 0 | M18: 58.872 | N18: 1037 | O18: 81.095484 | P18: 0 | AM18: =+'ESTADO DECLARACIÓN CVP'!G18*'COSTO VARIABLE DE PRODUCCIÓN'!M18 -> 8516.0945 | AN18: =+VLOOKUP('ESTADO DECLARACIÓN CVP'!$C18,'COSTO VARIABLE DE PRODUCCIÓN'!$C$4:$K$57,9,FALSE) -> 8516.0945 | AO18: =+AM18=AN18 -> TRUE
A19: 2026-06-06 - 2026-06-12 | B19: DPP | C19: G3PEMCT | D19: Gas Natural | E19: 934.593 | F19: 0 | G19: 934.593 | H19: 0.0084866169 | I19: 7931.5327 | J19: 475.89196 | K19: 8407.4247 | L19: 0 | M19: 58.872 | N19: 1037 | O19: 117.83258 | P19: 0 | AM19: =+'ESTADO DECLARACIÓN CVP'!G19*'COSTO VARIABLE DE PRODUCCIÓN'!M19 -> 11755.092 | AN19: =+VLOOKUP('ESTADO DECLARACIÓN CVP'!$C19,'COSTO VARIABLE DE PRODUCCIÓN'!$C$4:$K$57,9,FALSE) -> 11755.092 | AO19: =+AM19=AN19 -> TRUE
A20: 2026-06-06 - 2026-06-12 | B20: DPP | C20: G3PEMCP | D20: Gas Natural | E20: 934.593 | F20: 0 | G20: 934.593 | H20: 0.0085963103 | I20: 8034.0514 | J20: 482.04308 | K20: 8516.0945 | L20: 0 | M20: 58.872 | N20: 1037 | O20: 116.32898 | P20: 0 | AM20: =+'ESTADO DECLARACIÓN CVP'!G20*'COSTO VARIABLE DE PRODUCCIÓN'!M20 -> 11678.667 | AN20: =+VLOOKUP('ESTADO DECLARACIÓN CVP'!$C20,'COSTO VARIABLE DE PRODUCCIÓN'!$C$4:$K$57,9,FALSE) -> 11678.667 | AO20: =+AM20=AN20 -> TRUE
A21: 2026-06-06 - 2026-06-12 | B21: ENERGíA 2000 | C21: G3MPLACS | D21: Gas Natural | E21: 768.87654 | F21: 0 | G21: 768.87654 | H21: 0.013549122 | I21: 10417.602 | J21: 208.35204 | K21: 10625.954 | L21: 1070828 | M21: 58.872 | N21: 1032.9 | O21: 12341.169 | P21: 0 | AM21: =+'ESTADO DECLARACIÓN CVP'!G21*'COSTO VARIABLE DE PRODUCCIÓN'!M21 -> 10625.954 | AN21: =+VLOOKUP('ESTADO DECLARACIÓN CVP'!$C21,'COSTO VARIABLE DE PRODUCCIÓN'!$C$4:$K$57,9,FALSE) -> 10625.954 | AO21: =+AM21=AN21 -> TRUE
A22: 2026-06-06 - 2026-06-12 | B22: EGEHAINA | C22: G3QUI2FO | D22: Fuel Oil No. 6 | E22: 114.50183 | F22: 11.466023 | G22: 125.96786 | H22: 0.053938112 | I22: 6794.4684 | J22: 135.88936 | K22: 6930.3577 | L22: 2056101.4 | M22: 58.872 | N22: 140721 | O22: 7322.5865 | P22: 976.9 | AM22: =+'ESTADO DECLARACIÓN CVP'!G22*'COSTO VARIABLE DE PRODUCCIÓN'!M22 -> 3469.4568 | AN22: =+VLOOKUP('ESTADO DECLARACIÓN CVP'!$C22,'COSTO VARIABLE DE PRODUCCIÓN'!$C$4:$K$57,9,FALSE) -> 3469.4568 | AO22: =+AM22=AN22 -> TRUE
A23: 2026-06-06 - 2026-06-12 | B23: EGEHAINA | C23: G3HTG | D23: Fuel Oil No. 2 | E23: 138.81429 | F23: 0.70085714 | G23: 139.51515 | H23: 0.090062012 | I23: 12565.015 | J23: 251.30026 | K23: 12816.315 | L23: 161238.24 | M23: 58.872 | N23: 130417 | O23: 11390.896 | P23: 864.6 | AM23: =+'ESTADO DECLARACIÓN CVP'!G23*'COSTO VARIABLE DE PRODUCCIÓN'!M23 -> 3825.8278 | AN23: =+VLOOKUP('ESTADO DECLARACIÓN CVP'!$C23,'COSTO VARIABLE DE PRODUCCIÓN'!$C$4:$K$57,9,FALSE) -> 3825.8278 | AO23: =+AM23=AN23 -> TRUE
A24: 2026-06-06 - 2026-06-12 | B24: EGEHAINA | C24: G3SESTE | D24: Fuel Oil No. 6 | E24: 114.50183 | F24: 11.466023 | G24: 125.96786 | H24: 0.057502679 | I24: 7243.4893 | J24: 289.73957 | K24: 7533.2288 | L24: 4123070.1 | M24: 58.872 | N24: 140647 | O24: 7897.9556 | P24: 968.5 | AM24: =+'ESTADO DECLARACIÓN CVP'!G24*'COSTO VARIABLE DE PRODUCCIÓN'!M24 -> 12816.315 | AN24: =+VLOOKUP('ESTADO DECLARACIÓN CVP'!$C24,'COSTO VARIABLE DE PRODUCCIÓN'!$C$4:$K$57,9,FALSE) -> 12816.315 | AO24: =+AM24=AN24 -> TRUE
A25: 2026-06-06 - 2026-06-12 | B25: EGEHAINA | C25: G3BCARBO | D25: Carbón | E25: 4560.2251 | F25: 1139.1732 | G25: 5699.3983 | H25: 0.00059668372 | I25: 3400.7382 | J25: 425.08962 | K25: 3825.8278 | L25: 14091.7 | M25: 58.872 | N25: 10706 | O25: 13901.786 | P25: 0 | AM25: =+'ESTADO DECLARACIÓN CVP'!G25*'COSTO VARIABLE DE PRODUCCIÓN'!M25 -> 7533.2288 | AN25: =+VLOOKUP('ESTADO DECLARACIÓN CVP'!$C25,'COSTO VARIABLE DE PRODUCCIÓN'!$C$4:$K$57,9,FALSE) -> 7533.2288 | AO25: =+AM25=AN25 -> TRUE
A26: 2026-06-06 - 2026-06-12 | B26: EGEHAINA | C26: G3QUI2GN | D26: Gas Natural | E26: 422.11094 | F26: 0 | G26: 422.11094 | H26: 0.0080581379 | I26: 3401.4282 | J26: 68.028581 | K26: 3469.4568 | L26: 0 | M26: 58.872 | N26: 931.53 | O26: 0.00805814 | P26: 0 | AM26: =+'ESTADO DECLARACIÓN CVP'!G26*'COSTO VARIABLE DE PRODUCCIÓN'!M26 -> 6930.3577 | AN26: =+VLOOKUP('ESTADO DECLARACIÓN CVP'!$C26,'COSTO VARIABLE DE PRODUCCIÓN'!$C$4:$K$57,9,FALSE) -> 6930.3577 | AO26: =+AM26=AN26 -> TRUE
A27: 2026-06-06 - 2026-06-12 | B27: EGEITABO | C27: G3ITABO2 | D27: Carbón | E27: 5535.7342 | F27: 737.8094 | G27: 6273.5436 | H27: 0.0004909923 | I27: 3080.2616 | J27: 154.01308 | K27: 3234.2746 | L27: 40098.375 | M27: 58.872 | N27: 0.0004909923 | O27: 2036.6918 | P27: 0 | AM27: =+'ESTADO DECLARACIÓN CVP'!G27 -> 14229.868 | AN27: =+VLOOKUP('ESTADO DECLARACIÓN CVP'!$C27,'COSTO VARIABLE DE PRODUCCIÓN'!$C$4:$K$57,9,FALSE) -> 14229.868 | AO27: =+AM27=AN27 -> TRUE
A28: 2026-06-06 - 2026-06-12 | B28: EGEITABO | C28: G3SLORE1 | D28: Fuel Oil No. 2 | E28: 147.6 | F28: 0 | G28: 147.6 | H28: 0.094517958 | I28: 13950.851 | J28: 279.01701 | K28: 14229.868 | L28: 11500 | M28: 58.872 | N28: 0 | O28: 10.58 | P28: 0.8671 | AM28: =+'ESTADO DECLARACIÓN CVP'!G28*'COSTO VARIABLE DE PRODUCCIÓN'!M28 -> 3423.1033 | AN28: =+VLOOKUP('ESTADO DECLARACIÓN CVP'!$C28,'COSTO VARIABLE DE PRODUCCIÓN'!$C$4:$K$57,9,FALSE) -> 3423.1033 | AO28: =+AM28=AN28 -> TRUE
A29: 2026-06-06 - 2026-06-12 | B29: EGEITABO | C29: G3ITABO1 | D29: Carbón | E29: 5504.532 | F29: 805.28369 | G29: 6309.8157 | H29: 0.00053713316 | I29: 3389.2112 | J29: 33.892112 | K29: 3423.1033 | L29: 40098.375 | M29: 58.872 | N29: 0.00053713316 | O29: 1861.7358 | P29: 0 | AM29: =+'ESTADO DECLARACIÓN CVP'!G29*'COSTO VARIABLE DE PRODUCCIÓN'!M29 -> 3234.2746 | AN29: =+VLOOKUP('ESTADO DECLARACIÓN CVP'!$C29,'COSTO VARIABLE DE PRODUCCIÓN'!$C$4:$K$57,9,FALSE) -> 3234.2746 | AO29: =+AM29=AN29 -> TRUE
A30: 2026-06-06 - 2026-06-12 | B30: EMPRESA DE GENERACIÓN ELÉCTRICA PUNTA CATALINA | C30: G3PCATA2 | D30: Carbón | E30: 3998.5274 | F30: 484.97636 | G30: 4483.5037 | H30: 0.00040802561 | I30: 1829.3843 | J30: 16.464459 | K30: 1845.8488 | L30: 116604.73 | M30: 58.872 | N30: 10126.5 | O30: 2450.8266 | P30: 0 | AM30: =+'ESTADO DECLARACIÓN CVP'!G30*'COSTO VARIABLE DE PRODUCCIÓN'!M30 -> 1845.8488 | AN30: =+VLOOKUP('ESTADO DECLARACIÓN CVP'!$C30,'COSTO VARIABLE DE PRODUCCIÓN'!$C$4:$K$57,9,FALSE) -> 1845.8488 | AO30: =+AM30=AN30 -> TRUE
A31: 2026-06-06 - 2026-06-12 | B31: EMPRESA DE GENERACIÓN ELÉCTRICA PUNTA CATALINA | C31: G3PCATA1 | D31: Carbón | E31: 3998.5274 | F31: 484.97636 | G31: 4483.5037 | H31: 0.00041774967 | I31: 1872.9822 | J31: 16.85684 | K31: 1889.839 | L31: 116604.73 | M31: 58.872 | N31: 10126.5 | O31: 2393.7781 | P31: 0 | AM31: =+'ESTADO DECLARACIÓN CVP'!G31*'COSTO VARIABLE DE PRODUCCIÓN'!M31 -> 1889.839 | AN31: =+VLOOKUP('ESTADO DECLARACIÓN CVP'!$C31,'COSTO VARIABLE DE PRODUCCIÓN'!$C$4:$K$57,9,FALSE) -> 1889.839 | AO31: =+AM31=AN31 -> TRUE
A32: 2026-06-06 - 2026-06-12 | B32: SEABOARD | C32: G3EM2SGN | D32: Gas Natural | E32: 621.05382 | F32: 0 | G32: 621.05382 | H32: 0.0089689482 | I32: 5570.1996 | J32: 222.80798 | K32: 5793.0076 | L32: 0 | M32: 58.872 | N32: 0 | O32: 9045.3913 | P32: 0 | AM32: =+'ESTADO DECLARACIÓN CVP'!G32*'COSTO VARIABLE DE PRODUCCIÓN'!M32 -> 5363.776 | AN32: =+VLOOKUP('ESTADO DECLARACIÓN CVP'!$C32,'COSTO VARIABLE DE PRODUCCIÓN'!$C$4:$K$57,9,FALSE) -> 5363.776 | AO32: =+AM32=AN32 -> TRUE
A33: 2026-06-06 - 2026-06-12 | B33: SEABOARD | C33: G3EM3CCP | D33: Gas Natural | E33: 486.87144 | F33: 0 | G33: 486.87144 | H33: 0.0074132204 | I33: 3609.2853 | J33: 67.47225 | K33: 3676.7576 | L33: 0 | M33: 58.872 | N33: 0 | O33: 7413.2204 | P33: 0 | AM33: =+'ESTADO DECLARACIÓN CVP'!G33*'COSTO VARIABLE DE PRODUCCIÓN'!M33 -> 5512.2649 | AN33: =+VLOOKUP('ESTADO DECLARACIÓN CVP'!$C33,'COSTO VARIABLE DE PRODUCCIÓN'!$C$4:$K$57,9,FALSE) -> 5512.2649 | AO33: =+AM33=AN33 -> TRUE
A34: 2026-06-06 - 2026-06-12 | B34: SEABOARD | C34: G3EM2SFO | D34: Fuel Oil No. 6 | E34: 119.89615 | F34: 10.78296 | G34: 130.67911 | H34: 0.057700493 | I34: 7540.249 | J34: 301.60996 | K34: 7841.8589 | L34: 1055648 | M34: 58.872 | N34: 146494.24 | O34: 8581.4188 | P34: 959.85265 | AM34: =+'ESTADO DECLARACIÓN CVP'!G34*'COSTO VARIABLE DE PRODUCCIÓN'!M34 -> 5793.0076 | AN34: =+VLOOKUP('ESTADO DECLARACIÓN CVP'!$C34,'COSTO VARIABLE DE PRODUCCIÓN'!$C$4:$K$57,9,FALSE) -> 5793.0076 | AO34: =+AM34=AN34 -> TRUE
A35: 2026-06-06 - 2026-06-12 | B35: SEABOARD | C35: G3EM2CGN | D35: Gas Natural | E35: 621.05382 | F35: 0 | G35: 621.05382 | H35: 0.0085342921 | I35: 5300.2548 | J35: 212.01018 | K35: 5512.2649 | L35: 0 | M35: 58.872 | N35: 0 | O35: 8346.8234 | P35: 0 | AM35: =+'ESTADO DECLARACIÓN CVP'!G35*'COSTO VARIABLE DE PRODUCCIÓN'!M35 -> 7449.2505 | AN35: =+VLOOKUP('ESTADO DECLARACIÓN CVP'!$C35,'COSTO VARIABLE DE PRODUCCIÓN'!$C$4:$K$57,9,FALSE) -> 7449.2505 | AO35: =+AM35=AN35 -> TRUE
A36: 2026-06-06 - 2026-06-12 | B36: SEABOARD | C36: G3EM2CFO | D36: Fuel Oil No. 6 | E36: 119.89615 | F36: 10.78296 | G36: 130.67911 | H36: 0.054811675 | I36: 7162.7408 | J36: 286.50963 | K36: 7449.2505 | L36: 1055648 | M36: 58.872 | N36: 146494.24 | O36: 7918.6831 | P36: 959.85265 | AM36: =+'ESTADO DECLARACIÓN CVP'!G36*'COSTO VARIABLE DE PRODUCCIÓN'!M36 -> 7841.8589 | AN36: =+VLOOKUP('ESTADO DECLARACIÓN CVP'!$C36,'COSTO VARIABLE DE PRODUCCIÓN'!$C$4:$K$57,9,FALSE) -> 7841.8589 | AO36: =+AM36=AN36 -> TRUE
A37: 2026-06-06 - 2026-06-12 | B37: SEABOARD | C37: G3EM3CCT | D37: Gas Natural | E37: 486.87144 | F37: 0 | G37: 486.87144 | H37: 0.0073122881 | I37: 3560.1443 | J37: 66.553604 | K37: 3626.6979 | L37: 0 | M37: 58.872 | N37: 0 | O37: 7312.2881 | P37: 0 | AM37: =+'ESTADO DECLARACIÓN CVP'!G37*'COSTO VARIABLE DE PRODUCCIÓN'!M37 -> 3626.6979 | AN37: =+VLOOKUP('ESTADO DECLARACIÓN CVP'!$C37,'COSTO VARIABLE DE PRODUCCIÓN'!$C$4:$K$57,9,FALSE) -> 3626.6979 | AO37: =+AM37=AN37 -> TRUE
A38: 2026-06-06 - 2026-06-12 | B38: SEABOARD | C38: G3EM3CS | D38: Gas Natural | E38: 486.87144 | F38: 0 | G38: 486.87144 | H38: 0.010814652 | I38: 5265.3453 | J38: 98.430759 | K38: 5363.776 | L38: 0 | M38: 58.872 | N38: 0 | O38: 10814.652 | P38: 0 | AM38: =+'ESTADO DECLARACIÓN CVP'!G38*'COSTO VARIABLE DE PRODUCCIÓN'!M38 -> 3676.7576 | AN38: =+VLOOKUP('ESTADO DECLARACIÓN CVP'!$C38,'COSTO VARIABLE DE PRODUCCIÓN'!$C$4:$K$57,9,FALSE) -> 3676.7576 | AO38: =+AM38=AN38 -> TRUE
A39: 2026-06-06 - 2026-06-12 | B39: GPLV | C39: G3LVEGA | D39: Fuel Oil No. 6 | E39: 136.9056 | F39: 3.9979796 | G39: 140.90358 | H39: 0.060858631 | I39: 8575.1991 | J39: 343.00796 | K39: 8918.2071 | L39: 737800.93 | M39: 58.872 | N39: 146402.51 | O39: 8909.8844 | P39: 931.27354 | AM39: =+'ESTADO DECLARACIÓN CVP'!G39*'COSTO VARIABLE DE PRODUCCIÓN'!M39 -> 8682.607 | AN39: =+VLOOKUP('ESTADO DECLARACIÓN CVP'!$C39,'COSTO VARIABLE DE PRODUCCIÓN'!$C$4:$K$57,9,FALSE) -> 8682.607 | AO39: =+AM39=AN39 -> TRUE
... A56: 2026-06-06 - 2026-06-12 | B56: SIBA | C56: G3SIBACS | D56: Gas Natural | E56: 1139.1732 | F56: 0 | G56: 1139.1732 | H56: 0.011251393 | I56: 12817.285 | J56: 256.0932 | K56: 13073.378 | L56: 0 | M56: 58.872 | N56: 1000 | O56: 0.0112513 | P56: 0 | AM56: =+'ESTADO DECLARACIÓN CVP'!G56*'COSTO VARIABLE DE PRODUCCIÓN'!M56 -> 13073.378 | AN56: =+VLOOKUP('ESTADO DECLARACIÓN CVP'!$C56,'COSTO VARIABLE DE PRODUCCIÓN'!$C$4:$K$57,9,FALSE) -> 13073.378 | AO56: =+AM56=AN56 -> TRUE
...

Sheet EXISTENCIA DE COMBUSTIBLE
B1: ORGANISMO COORDINADOR DEL SISTEMA ELÉCTRICO NACIONAL INTERCONECTADO
B2: ="EXISTENCIA DE COMBUSTIBLE " &ETIQUETA!O21 -> EXISTENCIA DE COMBUSTIBLE CVP_06-06_12-06-26
B3: EMPRESA | C3: CENTRAL | D3: TIPO COMBUSTIBLE | E3: COMBUSTIBLE | F3: ALMACENAMIENTO PRINCIPAL | G3: ALMACENAMIENTO DIARIO | H3: PUNTOS MUERTOS OPERACIÓN | I3: ESTADO DECLARACIÓN EAC | J3: CEN | K3: UNIDAD CEN | L3: COMBUSTIBLE ALMACENADO | M3: UNIDAD COMBUSTIBLE ALMACENADO | N3: ESTADO DECLARACIÓN COSTO | O3: ENERGÍA ALMACENADA (MWh)
B4: AES ANDRES | C4: G3AANDGN | D4: GASEOSO | E4: Gas Natural | I4: NO DECLARADO | J4: 0.0077921237 | K4: MMBTU/KWh | L4: 1369807.2 | M4: MMBTU | N4: APROBADO | O4: 175793.83
B5: AES ANDRES | C5: G3AANDFO | D5: LIQUIDO | E5: Fuel Oil No. 2 | I5: NO DECLARADO | J5: 0.057318422 | K5: GALONES/KWh | L5: 24500 | M5: GALONES | N5: APROBADO | O5: 427.43675
B6: BERSAL | C6: G3BERSAL | D6: LIQUIDO | E6: Fuel Oil No. 6 | I6: NO DECLARADO | J6: 0.060526176 | K6: GALONES/KWh | L6: 84351.216 | M6: GALONES | N6: APROBADO | O6: 1393.632
B7: CESPM | C7: G3CES1GN | D7: GASEOSO | E7: Gas Natural | I7: NO DECLARADO | J7: 0.0084025827 | K7: MMBTU/KWh | L7: 1936769.6 | M7: MMBTU | N7: APROBADO | O7: 230496.94
B8: CESPM | C8: G3CES1FO | D8: LIQUIDO | E8: Fuel Oil No. 2 | I8: NO DECLARADO | J8: 0.069981196 | K8: GALONES/KWh | L8: 236486.24 | M8: GALONES | N8: APROBADO | O8: 3379.2826
B9: CESPM | C9: G3CES2GN | D9: GASEOSO | E9: Gas Natural | I9: NO DECLARADO | J9: 0.0083295576 | K9: MMBTU/KWh | L9: 1936769.6 | M9: MMBTU | N9: APROBADO | O9: 232517.7
B10: CESPM | C10: G3CES2FO | D10: LIQUIDO | E10: Fuel Oil No. 2 | I10: NO DECLARADO | J10: 0.094942974 | K10: GALONES/KWh | L10: 236486.24 | M10: GALONES | N10: APROBADO | O10: 2490.824
B11: CESPM | C11: G3CES3GN | D11: GASEOSO | E11: Gas Natural | I11: NO DECLARADO | J11: 0.0083877907 | K11: MMBTU/KWh | L11: 1936769.6 | M11: MMBTU | N11: APROBADO | O11: 230903.42
B12: CESPM | C12: G3CES3FO | D12: LIQUIDO | E12: Fuel Oil No. 2 | I12: NO DECLARADO | J12: 0.063224967 | K12: GALONES/KWh | L12: 236486.24 | M12: GALONES | N12: APROBADO | O12: 3740.3932
B13: CESPM | C13: G3E4CCFO | D13: LIQUIDO | E13: Fuel Oil No. 2 | I13: NO DECLARADO | J13: 0.054945319 | K13: GALONES/KWh | L13: 236486.24 | M13: GALONES | N13: APROBADO | O13: 4304.0289
B14: CESPM | C14: G3E4CCGN | D14: GASEOSO | E14: Gas Natural | I14: NO DECLARADO | J14: 0.0072990159 | K14: MMBTU/KWh | L14: 410298.08 | M14: MMBTU | N14: APROBADO | O14: 56212.795
B15: METALDOM | C15: G3METALD | D15: LIQUIDO | E15: Fuel Oil No. 6 | I15: NO DECLARADO | K15: GALONES/KWh | M15: GALONES | N15: NO DECLARADO
B16: DOMICEM GENERACIÓN | C16: G3PALENQ | D16: LIQUIDO | E16: Fuel Oil No. 6 | I16: NO DECLARADO | J16: 0.063873081 | K16: GALONES/KWh | L16: 122050.1 | M16: GALONES | N16: APROBADO | O16: 1910.8222
B17: DPP | C17: G3PEMCT | D17: GASEOSO | E17: Gas Natural | I17: NO DECLARADO | J17: 0.0084866169 | K17: MMBTU/KWh | L17: 0 | M17: MMBTU | N17: APROBADO | O17: 0
B18: DPP | C18: G3PEMCP | D18: GASEOSO | E18: Gas Natural | I18: NO DECLARADO | J18: 0.0085963103 | K18: MMBTU/KWh | L18: 0 | M18: MMBTU | N18: APROBADO | O18: 0
B19: DPP | C19: G3LMINA5 | D19: GASEOSO | E19: Gas Natural | I19: NO DECLARADO | J19: 0.012250973 | K19: MMBTU/KWh | L19: 0 | M19: MMBTU | N19: APROBADO | O19: 0
B20: DPP | C20: G3LMINA6 | D20: GASEOSO | E20: Gas Natural | I20: NO DECLARADO | J20: 0.012331143 | K20: MMBTU/KWh | L20: 0 | M20: MMBTU | N20: APROBADO | O20: 0
B21: ENERGíA 2000 | C21: G3MPLACS | D21: GASEOSO | E21: Gas Natural | I21: NO DECLARADO | J21: 0.013549122 | K21: MMBTU/KWh | L21: 1070828 | M21: MMBTU | N21: APROBADO | O21: 79033.017
B22: EGEHAINA | C22: G3QUI2FO | D22: LIQUIDO | E22: Fuel Oil No. 6 | I22: NO DECLARADO | J22: 0.053938112 | K22: GALONES/KWh | L22: 2056101.4 | M22: GALONES | N22: APROBADO | O22: 38119.641
B23: EGEHAINA | C23: G3QUI2GN | D23: GASEOSO | E23: Gas Natural | I23: NO DECLARADO | J23: 0.0080581379 | K23: MMBTU/KWh | L23: 0 | M23: MMBTU | N23: APROBADO | O23: 0
B24: EGEHAINA | C24: G3BCARBO | D24: SOLIDO | E24: Carbón | I24: NO DECLARADO | J24: 0.00059668372 | K24: TONELADAS METRICAS/KWh | L24: 14091.7 | M24: TONELADAS METRICAS | N24: APROBADO | O24: 23616.699
B25: EGEHAINA | C25: G3HTG | D25: LIQUIDO | E25: Fuel Oil No. 2 | I25: NO DECLARADO | J25: 0.090062012 | K25: GALONES/KWh | L25: 161238.24 | M25: GALONES | N25: APROBADO | O25: 1790.3024
B26: EGEHAINA | C26: G3SESTE | D26: LIQUIDO | E26: Fuel Oil No. 6 | I26: NO DECLARADO | J26: 0.057502679 | K26: GALONES/KWh | L26: 4123070.1 | M26: GALONES | N26: APROBADO | O26: 71702.226
B27: EGEITABO | C27: G3ITABO1 | D27: SOLIDO | E27: Carbón | I27: NO DECLARADO | J27: 0.00053713316 | K27: TONELADAS METRICAS/KWh | L27: 40098.375 | M27: TONELADAS METRICAS | N27: APROBADO | O27: 74652.578
B28: EGEITABO | C28: G3ITABO2 | D28: SOLIDO | E28: Carbón | I28: NO DECLARADO | J28: 0.0004909923 | K28: TONELADAS METRICAS/KWh | L28: 40098.375 | M28: TONELADAS METRICAS | N28: APROBADO | O28: 81668.033
B29: EGEITABO | C29: G3SLORE1 | D29: LIQUIDO | E29: Fuel Oil No. 2 | I29: NO DECLARADO | K29: GALONES/KWh | M29: GALONES | N29: NO DECLARADO
B30: EMPRESA DE GENERACIÓN ELÉCTRICA PUNTA CATALINA | C30: G3PCATA1 | D30: SOLIDO | E30: Carbón | I30: NO DECLARADO | J30: 0.00041774967 | K30: TONELADAS METRICAS/KWh | L30: 116604.73 | M30: TONELADAS METRICAS | N30: APROBADO | O30: 279125.84
B31: EMPRESA DE GENERACIÓN ELÉCTRICA PUNTA CATALINA | C31: G3PCATA2 | D31: SOLIDO | E31: Carbón | I31: NO DECLARADO | J31: 0.00040802561 | K31: TONELADAS METRICAS/KWh | L31: 116604.73 | M31: TONELADAS METRICAS | N31: APROBADO | O31: 285777.96
B32: SEABOARD | C32: G3EM2CGN | D32: GASEOSO | E32: Gas Natural | I32: NO DECLARADO | K32: MMBTU/KWh | M32: MMBTU | N32: NO DECLARADO
B33: SEABOARD | C33: G3EM2SGN | D33: GASEOSO | E33: Gas Natural | I33: NO DECLARADO | K33: MMBTU/KWh | M33: MMBTU | N33: NO DECLARADO
B34: SEABOARD | C34: G3EM2CFO | D34: LIQUIDO | E34: Fuel Oil No. 6 | I34: NO DECLARADO | K34: GALONES/KWh | M34: GALONES | N34: NO DECLARADO
B35: SEABOARD | C35: G3EM2SFO | D35: LIQUIDO | E35: Fuel Oil No. 6 | I35: NO DECLARADO | K35: GALONES/KWh | M35: GALONES | N35: NO DECLARADO
B36: SEABOARD | C36: G3EM3CS | D36: GASEOSO | E36: Gas Natural | I36: NO DECLARADO | K36: MMBTU/KWh | M36: MMBTU | N36: NO DECLARADO
B37: SEABOARD | C37: G3EM3CCP | D37: GASEOSO | E37: Gas Natural | I37: NO DECLARADO | K37: MMBTU/KWh | M37: MMBTU | N37: NO DECLARADO
B38: SEABOARD | C38: G3EM3CCT | D38: GASEOSO | E38: Gas Natural | I38: NO DECLARADO | K38: MMBTU/KWh | M38: MMBTU | N38: NO DECLARADO
B39: GPLV | C39: G3LVEGA | D39: LIQUIDO | E39: Fuel Oil No. 6 | I39: NO DECLARADO | J39: 0.060858631 | K39: GALONES/KWh | L39: 737800.93 | M39: GALONES | N39: APROBADO | O39: 12123.193
B40: GPLV | C40: G3PALAMA | D40: LIQUIDO | E40: Fuel Oil No. 6 | F40: 2113383 | G40: 0 | H40: 302265 | I40: NO APROBADO | J40: 0.060427654 | K40: GALONES/KWh | L40: 906319.08 | M40: GALONES | N40: APROBADO | O40: 14998.416
...
